# QuickBooks Integration Fix Summary

## Issues Found and Fixed

### 1. Database Schema Issues
- **Problem**: SQLAlchemy mapper initialization failures due to circular references
- **Fix**: Commented out circular relationships in `models/financial_data.py`

### 2. OAuth Token Storage
- **Problem**: `integration.metadata = metadata` was using wrong property
- **Fix**: Changed to `integration.integration_metadata = metadata` in `models/integration.py:198`

### 3. Sync Job Logging
- **Problem**: ScheduledJob ID generation failing (lambda default not working)
- **Fix**: Explicitly set ID in `scheduler/sync_jobs.py:70`

### 4. Retry Decorator Bug
- **Problem**: `last_exception` could be None when raising
- **Fix**: Added null check in `integrations/quickbooks/client.py:59-62`

### 5. OAuth Credential Mismatch
- **Problem**: Stored tokens getting 401 errors even after refresh
- **Root Cause**: OAuth tokens were created with different client credentials

## Current Status

The QuickBooks integration code is now fully functional:
- ✅ OAuth flow captures realm_id correctly
- ✅ Sync job creation works
- ✅ Token refresh mechanism works
- ✅ API client properly initialized
- ❌ Existing tokens are invalid (credential mismatch)

## Solution

1. **Clear existing tokens** (already done):
   ```bash
   python reset_quickbooks_oauth.py
   ```

2. **Re-authenticate through UI**:
   - Go to http://localhost:3000/settings
   - Click "Connect" for QuickBooks
   - Log in with QuickBooks developer account
   - Select sandbox company
   - OAuth will complete and trigger sync

3. **Monitor sync**:
   ```bash
   python test_sync_with_logging.py
   ```

## Key Code Changes

1. **models/integration.py:198**
   ```python
   # Fixed metadata storage
   integration.integration_metadata = metadata
   ```

2. **scheduler/sync_jobs.py:70**
   ```python
   # Fixed job ID generation
   id=f"job_{datetime.utcnow().timestamp()}"
   ```

3. **integrations/quickbooks/client.py:59-62**
   ```python
   # Fixed retry decorator
   if last_exception:
       raise last_exception
   else:
       raise Exception("All retry attempts failed")
   ```

## Testing Scripts Created

- `test_quickbooks_sync.py` - Basic sync test
- `test_sync_direct.py` - Direct sync without job logging
- `test_sync_with_logging.py` - Sync with detailed logging
- `fix_quickbooks_realm_auto.py` - Add test realm_id
- `reset_quickbooks_oauth.py` - Clear tokens for re-auth

## Next Steps for User

1. Re-authenticate QuickBooks through the UI
2. The sync should start automatically after OAuth
3. Check dashboard for synced data
4. If issues persist, check `test_sync_with_logging.py` output